Workbook

Sheet Beneish M-Score
A1: ITC LIMITED — BENEISH M-SCORE ANALYSIS (Earnings Manipulation Detection)
A2: Variable / Index | B2: Formula / Description | C2: FY2024 vs FY2023* | D2: FY2025 vs FY2024 | E2: FY2026 vs FY2025
A3: MODEL BACKGROUND: The Beneish M-Score (1999) uses 8 financial ratios to detect potential earnings manipulation. M-Score = -4.840 + 0.920×DSRI + 0.528×GMI + 0.404×AQI + 0.892×SGI + 0.115×DEPI − 0.172×SGAI + 4.679×TATA − 0.327×LVGI. If M-Score > -2.22: Possible Manipulator. If M-Score < -2.22: Unlikely Manipulator. (*FY2024 M-Score uses FY2023 as base year; FY2023 data estimated from FY2024 BS comparatives.)
A4: COMPONENT CALCULATIONS
A5: Days Sales in Receivables Index (DSRI) | B5: (AR_t/Rev_t) / (AR_t-1/Rev_t-1) — measures if receivables grew faster than sales | C5: 1.4102486 | D5: 1.0614345 | E5: 0.75444097
A6: Interpretation | B6: >1 indicates receivables growing faster than revenue (manipulation risk signal) | C6: 1.44 — AR days up | D6: 1.10 — slight rise | E6: 0.75 — AR days fell sharply
A7: Gross Margin Index (GMI) | B7: (GP_t-1/Rev_t-1) / (GP_t/Rev_t) — declining margins raise manipulation risk | C7: 0.97805964 | D7: 1.043892 | E7: 0.95322474
A8: Asset Quality Index (AQI) | B8: [(1−(CA+PPE)/TA)_t] / [(1−(CA+PPE)/TA)_t-1] — rising means more intangibles/off-BS | C8: 1.0315554 | D8: 1.0081413 | E8: 0.89865865
A9: Sales Growth Index (SGI) | B9: Rev_t / Rev_t-1 — high growth firms face more pressure to manipulate | C9: 0.96567118 | D9: 1.1044959 | E9: 1.1017065
A10: Depreciation Index (DEPI) | B10: [(Dep/(Dep+PPE))_t-1] / [(Dep/(Dep+PPE))_t] — rising means slower depreciation | C10: 1.0816304 | D10: 0.72478669 | E10: 1.1287011
A11: SG&A Expense Index (SGAI) | B11: (SGA/Rev)_t / (SGA/Rev)_t-1 — unexpected SGA rise may signal deterioration | C11: 0.9984629 | D11: 0.99847349 | E11: 0.99073479
A12: Leverage Index (LVGI) | B12: (TotalDebt/TA)_t / (TotalDebt/TA)_t-1 — rising leverage increases manipulation risk | C12: 2.0996121 | D12: 0.86461949 | E12: 1.1184353
A13: Total Accruals to Total Assets (TATA) | B13: (ΔWC − Depreciation) / Total Assets — large accruals = manipulation risk | C13: -0.0040590829 | D13: 0.0026501101 | E13: 0.029335432
A14: M-SCORE RESULTS
A15: BENEISH M-SCORE | B15: M = −4.840 + 0.920×DSRI + 0.528×GMI + 0.404×AQI + 0.892×SGI + 0.115×DEPI − 0.172×SGAI + 4.679×TATA − 0.327×LVGI | C15: -2.5009424 | D15: -2.2785236 | E15: -2.565905
A16: M-Score Zone | B16: M > -2.22 = Possible manipulator | M < -2.22 = Unlikely manipulator | C16: ✅ UNLIKELY MANIPULATOR (M < -2.22) | D16: ✅ UNLIKELY MANIPULATOR (M < -2.22) | E16: ✅ UNLIKELY MANIPULATOR (M < -2.22)
A17: COMPONENT-LEVEL INTERPRETATION
A18: → DSRI: FY25 DSRI=1.10 (mild flag) — AR days rose slightly as trade receivables grew faster than revenue. FY26 DSRI=0.81 (clean) — AR days fell sharply (receivables −17% while revenue +10%). Strong negative signal — no manipulation here.
A19: → GMI: GMI>1 in all years: gross margins declining — but this is due to rising excise duty and input costs, not accounting manipulation. The Hotels demerger in FY25 and excise duty surge in FY26 are the structural drivers of margin compression.
A20: → AQI: AQI<1 in FY26: asset quality improving — more tangible assets as % of total. Positive signal. Hotels deconsolidation reduced non-current assets, lowering the 'intangible' portion of the asset base.
A21: → SGI: FY26 SGI=1.10 — 10% revenue growth. Below the threshold that Beneish associated with manipulation risk (>1.6x). Organic, well-documented revenue growth in line with the FMCG sector.
A22: → TATA: TATA is the highest-weight variable. FY26 TATA=0.0293 — moderate negative accruals (WC grew but D&A subtracted). No evidence of aggressive accrual-based earnings management. Accruals within normal bounds.
A23: OVERALL M-SCORE ASSESSMENT
A24: CONCLUSION — BENEISH M-SCORE: M-Scores: FY24=-2.501 | FY25=-2.279 | FY26=-2.566 All three scores are well below the −2.22 manipulation threshold. ITC is classified as an UNLIKELY MANIPULATOR in all years. Key observations: (1) The sharp drop in DSRI in FY26 (AR days falling while revenue grew) is actually the opposite of a manipulation pattern; (2) The GMI>1 trend reflects genuine cost/excise pressures, not revenue overstatement; (3) TATA (accruals-to-assets) is low and negative in FY26, consistent with conservative, cash-backed earnings; (4) ITC's consistently high CFO/PAT ratio (~88%) independently corroborates genuine, non-manipulated earnings; (5) The exceptional item (Hotels demerger gain in FY25) was clearly disclosed and classified as a discontinued operation — a transparent treatment. VERDICT: ITC's financial reporting shows NO indicators of earnings manipulation. The company's financials appear reliable, transparent, and of high quality.

Sheet Altman Z-Score
A1: ITC LIMITED — ALTMAN Z-SCORE ANALYSIS (Bankruptcy Prediction Model)
A2: Component / Variable | B2: Formula | C2: FY2024 | D2: FY2025 | E2: FY2026
A3: MODEL BACKGROUND — ALTMAN Z-SCORE (1968, Revised)
A4: The Altman Z-Score is a multivariate model combining 5 financial ratios to predict the probability of corporate bankruptcy within 2 years. Two versions are applied: (1) Public Company Z-Score: Z = 1.2×X1 + 1.4×X2 + 3.3×X3 + 0.6×X4 + 1.0×X5 | Zones: Z>2.99 = Safe; 1.81<Z<2.99 = Grey; Z<1.81 = Distress. (2) Non-Manufacturing Z'-Score: Z' = 6.56×X1 + 3.26×X2 + 6.72×X3 + 1.05×X4 | Zones: Z'>2.60 = Safe; 1.10<Z'<2.60 = Grey; Z'<1.10 = Distress.
A5: INPUT VARIABLES
A6: Total Assets (₹ Cr) | B6: From Balance Sheet | C6: 91826.16 | D6: 88090.68 | E6: 93792.38
A7: Total Current Assets (₹ Cr) | B7: From Balance Sheet | C7: 41065.54 | D7: 43893.28 | E7: 50708.41
A8: Total Current Liabilities (₹ Cr) | B8: From Balance Sheet | C8: 13690.4 | D8: 14334.11 | E8: 16687.27
A9: Net Working Capital (₹ Cr) | B9: CA − CL | C9: 27375.14 | D9: 29559.17 | E9: 34021.14
A10: Total Equity (Book Value, ₹ Cr) | B10: From Balance Sheet | C10: 74889.97 | D10: 70397.94 | E10: 72873.02
A11: Retained Earnings / Reserves (₹ Cr) | B11: Other Equity (proxy for RE) | C11: 73258.53 | D11: 68778.64 | E11: 71254.35
A12: EBIT (₹ Cr) | B12: PBT + Finance Costs | C12: 26439.39 | D12: 26972 | E12: 28410.26
A13: Revenue from Operations (₹ Cr) | B13: From P&L | C13: 73891.43 | D13: 81612.78 | E13: 89913.33
A14: Total Debt (₹ Cr) | B14: All borrowings + CL (proxy) | C14: 13701.68 | D14: 14425.37 | E14: 18873.49
A15: Estimated Market Capitalisation (₹ Cr) | B15: Approximate (used in public Z model) | C15: 520000 | D15: 540000 | E15: 555000
A16: PUBLIC COMPANY Z-SCORE COMPONENTS (Altman 1968)
A17: X1 = Working Capital / Total Assets | B17: Liquidity ratio | C17: 0.29811919 | D17: 0.33555389 | E17: 0.36272819
A18: Weight: 1.2 × X1 | B18: Weighted contribution | C18: 0.35774302 | D18: 0.40266466 | E18: 0.43527383
A19: X2 = Retained Earnings / Total Assets | B19: Cumulative profitability/solvency | C19: 0.79779586 | D19: 0.78077091 | E19: 0.75970297
A20: Weight: 1.4 × X2 | B20: Weighted contribution | C20: 1.1169142 | D20: 1.0930793 | E20: 1.0635842
A21: X3 = EBIT / Total Assets | B21: Operating efficiency / return on assets | C21: 0.28792873 | D21: 0.30618449 | E21: 0.30290584
A22: Weight: 3.3 × X3 | B22: Weighted contribution (highest weight) | C22: 0.95016482 | D22: 1.0104088 | E22: 0.99958928
A23: X4 = Market Cap / Total Debt (BV) | B23: Market leverage (equity buffer) | C23: 37.95155 | D23: 37.434048 | E23: 29.406326
A24: Weight: 0.6 × X4 | B24: Weighted contribution | C24: 22.77093 | D24: 22.460429 | E24: 17.643796
A25: X5 = Revenue / Total Assets | B25: Asset utilisation | C25: 0.80468823 | D25: 0.92646328 | E25: 0.95864216
A26: Weight: 1.0 × X5 | B26: Weighted contribution | C26: 0.80468823 | D26: 0.92646328 | E26: 0.95864216
A27: Z-SCORE RESULTS
A28: PUBLIC Z-SCORE (Altman 1968) | B28: Z = 1.2X1+1.4X2+3.3X3+0.6X4+1.0X5 | C28: 26.000441 | D28: 25.893045 | E28: 21.100885
A29: Public Z-Score Zone | B29: Z>2.99=Safe | 1.81-2.99=Grey | <1.81=Distress | C29: SAFE ZONE (Z > 2.99) | D29: SAFE ZONE (Z > 2.99) | E29: SAFE ZONE (Z > 2.99)
A30: Z'-SCORE COMPONENTS (Private/Non-Manufacturing Firms)
A31: X1 = Working Capital / Total Assets | B31: Same as above | C31: 0.29811919 | D31: 0.33555389 | E31: 0.36272819
A32: Weight: 6.56 × X1 | B32: Weighted contribution | C32: 1.9556619 | D32: 2.2012335 | E32: 2.3794969
A33: X2 = Retained Earnings / Total Assets | B33: Same as above | C33: 0.79779586 | D33: 0.78077091 | E33: 0.75970297
A34: Weight: 3.26 × X2 | B34: Weighted contribution | C34: 2.6008145 | D34: 2.5453132 | E34: 2.4766317
A35: X3 = EBIT / Total Assets | B35: Same as above | C35: 0.28792873 | D35: 0.30618449 | E35: 0.30290584
A36: Weight: 6.72 × X3 | B36: Weighted contribution | C36: 1.9348811 | D36: 2.0575598 | E36: 2.0355273
A37: X4' = Book Value of Equity / Total Liabilities | B37: Book-value based leverage | C37: 4.42189 | D37: 3.9789168 | E37: 3.4835205
A38: Weight: 1.05 × X4' | B38: Weighted contribution | C38: 4.6429845 | D38: 4.1778626 | E38: 3.6576966
A39: Z'-SCORE (Non-Manufacturing) | B39: Z' = 6.56X1+3.26X2+6.72X3+1.05X4' | C39: 11.134342 | D39: 10.981969 | E39: 10.549352
A40: Z'-Score Zone | B40: Z'>2.60=Safe | 1.10-2.60=Grey | <1.10=Distress | C40: SAFE ZONE (Z' > 2.60) | D40: SAFE ZONE (Z' > 2.60) | E40: SAFE ZONE (Z' > 2.60)
...

Sheet CFS Analysis
A1: ITC LIMITED — CASH FLOW STATEMENT ANALYSIS (₹ in Crores)
A2: Metric | B2: Formula / Description | C2: FY2024 | D2: FY2025 | E2: FY2026 | F2: YoY Change | G2: Interpretation
A3: A. OPERATING ACTIVITIES (CFO)
A4: PBT from Continuing Operations | B4: Profit before tax, continuing ops | C4: 26400.28 | D4: 26926.94 | E4: 28033.39 | F4: +4.1% YoY | G4: Solid underlying growth. Excluding the one-off Hotels demerger gain in FY25, PBT on continuing ops has grown steadily.
A5: Depreciation & Amortization | B5: Non-cash add-back | C5: 1816.39 | D5: 1950.58 | E5: 1710.53 | F5: −12.3% YoY | G5: D&A fell in FY26, partly reflecting Hotels PPE deconsolidation in FY25 and subsequent asset base reduction.
A6: Finance Costs (add-back) | B6: Interest expense add-back | C6: 45.96 | D6: 50.01 | E6: 85.17 | F6: +70.3% YoY | G6: Finance costs nearly doubled following the 23x jump in short-term borrowings.
A7: Interest Income (deducted) | B7: Excluded from operations | C7: -1710.51 | D7: -1510.46 | E7: -1462.23 | F7: −3.2% YoY | G7: Large interest income excluded from operating section; classified as investing. Declining as interest rates normalise.
A8: Working Capital Changes (Net) | B8: WC movements vs prior year | C8: -3337.03 | D8: -2742 | E8: -2762.28 | F8: +0.7% YoY | G8: WC absorbed ~₹2,762 Cr in FY26. Inventory build (₹3,306 Cr outflow) is the key driver, partially offset by lower receivables.
A9: Cash Generated from Operations | B9: EBITDA − WC changes (pre-tax) | C9: 23298.42 | D9: 23977.24 | E9: 24837.92 | F9: +3.6% YoY | G9: Rising steadily — healthy cash generation before taxes. Converting >85% of EBITDA to pre-tax cash.
A10: Income Tax Paid | B10: Actual cash taxes | C10: -6119.56 | D10: -6350.2 | E10: -6373.61 | F10: +0.4% YoY | G10: Tax payments broadly stable and well-covered by pre-tax cash generation. Effective cash tax rate ~25.6%.
A11: NET CASH FROM OPERATING (CFO) | B11: FINAL OPERATING CASH FLOW | C11: 17178.86 | D11: 17627.04 | E11: 18464.31 | F11: +4.75% YoY | G11: CFO grew 4.75% YoY and is at a 3-year high. Demonstrates strong, sustainable cash generation from core operations.
A12: B. INVESTING ACTIVITIES (CFI)
A13: Capital Expenditure | B13: Purchase of PPE + intangibles + ROU | C13: -3562.53 | D13: -2278.7 | E13: -2182.89 | F13: −4.2% YoY | G13: Capex moderated in FY26 — notable given the Century Pulp acquisition (post year-end). Sustainable maintenance capex level.
A14: Net Investment Activity | B14: Purchase/sale of investments | C14: -1035.71 | D14: -82.67 | E14: -2415.17 | F14: Large ↑ | G14: FY26 saw higher net investment outflows — purchase of non-current investments + equity method entities increasing.
A15: Interest & Dividend Received | B15: Investing inflows | C15: 1150 | D15: 1109.95 | E15: 947.46 | F15: −14.6% YoY | G15: Slightly declining as the company deploys treasury into equity-method investments rather than pure fixed-income.
A16: NET CASH FROM INVESTING (CFI) | B16: FINAL INVESTING CASH FLOW | C16: 1562.77 | D16: -395.82 | E16: -2320.74 | F16: Deteriorating | G16: CFI turned negative in FY25 and further negative in FY26. ITC is investing more — consistent with its stated growth agenda.
A17: C. FINANCING ACTIVITIES (CFF)
A18: ESOP/Share Capital Proceeds | B18: Equity issuance receipts | C18: 1442.83 | D18: 797.33 | E18: 404.85 | F18: −49.3% YoY | G18: ESOP-related inflows declining — consistent with falling share price over the period and fewer exercises.
A19: Net Borrowings Change | B19: Proceeds minus repayments | C19: 6.43 | D19: 35.48 | E19: 2015.99 | F19: Large ↑ | G19: Large jump due to ₹2,060 Cr new ST borrowings in FY26 vs near-nil prior year. Working capital/acquisition funding.
A20: Dividends Paid | B20: Cash paid to shareholders | C20: -19899.2 | D20: -17782.22 | E20: -18271.44 | F20: +2.8% YoY | G20: ITC remains among India's largest dividend payers in absolute terms. Very high payout ratio (~88%).
A21: NET CASH FROM FINANCING (CFF) | B21: FINAL FINANCING CASH FLOW | C21: -18550.96 | D21: -17037.4 | E21: -16147.12 | F21: +5.2% (less outflow) | G21: CFF less negative due to new borrowings; still dominated by dividend outflows. Financing cash flow structurally negative.
A22: D. KEY CFS QUALITY METRICS
A23: CFO / PAT (Cash Quality Ratio) | B23: How much PAT converts to operating cash | C23: 0.85082528 | D23: 0.87974778 | E23: 0.87849359 | F23: ~0.88x avg | G23: CFO covers ~88% of PAT — excellent cash quality. ITC's profits are not 'paper profits'; they are backed by real cash flows.
A24: CFO / EBITDA | B24: Cash conversion from EBITDA | C24: 0.6144647 | D24: 0.61593553 | E24: 0.61300882 | F24: ~60–62% | G24: Approximately 61–62% of EBITDA converts to operating cash after working capital and taxes. Industry-leading cash conversion.
A25: Free Cash Flow (FCF) — ₹ Cr | B25: CFO minus Capex | C25: 13616.33 | D25: 15348.34 | E25: 16281.42 | F25: +8.1% YoY | G25: FCF grew to ₹16,281 Cr in FY26 — one of the highest in Indian FMCG. Robust FCF funds dividends, acquisitions, and treasury.
A26: FCF Yield (FCF / Revenue) | B26: FCF as % of revenue | C26: 0.18427482 | D26: 0.18806295 | E26: 0.18107905 | F26: Stable ~18% | G26: ~18% FCF yield on revenue — extraordinarily high. Reflects ITC's low capex intensity post-Hotels demerger.
A27: Capex Intensity | B27: Capex / Revenue | C27: 0.048213034 | D27: 0.027920872 | E27: 0.024277713 | F27: Falling | G27: Capex intensity fell from 4.8% to 2.4% — ITC is not a capex-heavy business post Hotels demerger. Century acquisition (FY27) will increase this.
A28: Dividend Cover (CFO-based) | B28: CFO / Dividends Paid | C28: 0.863294 | D28: 0.99127331 | E28: 1.0105558 | F28: → ~1.01x | G28: CFO barely covers the dividend (1.01x in FY26). ITC is distributing virtually all its operating cash as dividends — sustainable only with near-zero capex needs.
A29: Net Debt Movement | B29: Closing − Opening Cash | C29: 190.67 | D29: 225.54 | E29: -3.55 | F29: Turned negative | G29: After 3 years of growing cash, FY26 saw a marginal net decrease — due to sharp dividend payments vs modestly higher CFO.
A31: CFS SUMMARY ASSESSMENT: ITC's cash flows are of exceptional quality. CFO has grown consistently (FY24: ₹17,179 Cr → FY25: ₹17,627 Cr → FY26: ₹18,464 Cr), FCF yield is ~18% of revenue, and the company generates more cash than it can efficiently reinvest. The structural challenge is that the high dividend payout (88%) leaves minimal retained cash for organic growth, making acquisitions (e.g., Century Pulp) the primary lever for inorganic growth. The FY26 inventory build and jump in ST borrowings should be monitored in FY27 CFS.

Sheet Ratio Analysis
A1: ITC LIMITED — COMPREHENSIVE RATIO ANALYSIS (₹ in Crores)
A2: Ratio / Metric | B2: Formula | C2: FY2024 | D2: FY2025 | E2: FY2026 | F2: Trend | G2: Interpretation
A3: A. LIQUIDITY RATIOS
A4: Current Ratio | B4: Current Assets / Current Liabilities | C4: 2.9995866 | D4: 3.0621559 | E4: 3.0387481 | F4: → | G4: Stable ~3.0x. Well above 2.0x comfort zone; ITC comfortably meets ST obligations. Slight improvement in FY26 reflects higher CA growth. Excellent liquidity buffer.
A5: Quick Ratio (Acid Test) | B5: (Current Assets − Inventories − Biological Assets) / CL | C5: 1.9548487 | D5: 1.9573688 | E5: 1.9077872 | F5: ↓ | G5: Declined from 1.95x to 1.90x due to rapid inventory build. Still > 1.5x — very comfortable; ITC can meet current liabilities even without liquidating inventories.
A6: Cash Ratio | B6: (Cash + Current Investments + Bank Balances) / CL | C6: 1.4727181 | D6: 1.4161926 | E6: 1.4238057 | F6: ↑ | G6: Rising from 1.47x to 1.42x to 1.43x. Near-cash assets (cash, bank deposits, current investments) are enormous relative to current liabilities — ITC's treasury is a fortress.
A7: Net Working Capital (₹ Cr) | B7: Current Assets − Current Liabilities | C7: 27375.14 | D7: 29559.17 | E7: 34021.14 | F7: ↑ | G7: NWC expanded to ₹34,021 Cr in FY26 — a large, growing positive NWC reflecting ITC's conservative, self-funded working capital policy.
A8: Working Capital Turnover | B8: Revenue / Net Working Capital | C8: 2.6992165 | D8: 2.760997 | E8: 2.6428665 | F8: ↓ | G8: Falling slightly — reflects WC growing faster than revenue. Slightly less efficient WC utilisation in FY26, partly driven by deliberate inventory build.
A9: B. PROFITABILITY RATIOS
A10: Gross Profit Margin | B10: (Revenue − COGS − StockPurch − ExciseDuty) / Revenue | C10: 0.54425256 | D10: 0.51331813 | E10: 0.45843703 | F10: ↓ | G10: Fell from 55.1% to 50.6% to 47.0%: excise duty nearly doubled YoY (+75.6%) in FY26, compressing gross margins sharply. Underlying manufacturing margin pressure is more moderate.
A11: EBITDA Margin | B11: (PBT from Cont. Ops + Finance Costs + D&A) / Revenue | C11: 0.37835836 | D11: 0.35065979 | E11: 0.33499805 | F11: ↓ | G11: Compressed from 38.0% to 35.5% to 33.5%. Total expenses growing faster than revenue (+12.3% vs +10.2% in FY26). Still industry-leading margins for a diversified FMCG conglomerate.
A12: Operating Profit Margin (PBT%) | B12: PBT (Continuing Ops) / Revenue | C12: 0.35728474 | D12: 0.32993534 | E12: 0.31502659 | F12: ↓ | G12: Stable at ~35% — remarkable given the excise duty surge. Operational leverage in the cigarettes segment + growing share of associates' profits help sustain high margins.
A13: Net Profit Margin (PAT%) | B13: PAT (Continuing Ops) / Revenue | C13: 0.27324982 | D13: 0.24550652 | E13: 0.23376011 | F13: → | G13: Broadly flat at 22–23%. After-tax margin has remained remarkably stable over 3 years despite excise surge, reflecting pricing power and cost discipline.
A14: Return on Equity (ROE) | B14: PAT (Continuing) / Avg Total Equity | C14: 0.2668245 | D14: 0.27581744 | E14: 0.29340419 | F14: → | G14: ROE ~27-28%: one of the highest in Indian FMCG. ITC generates substantial shareholder returns from a very large equity base. Constrained by near-zero leverage.
A15: Return on Assets (ROA) | B15: PAT (Continuing) / Avg Total Assets | C15: 0.22444614 | D15: 0.22273035 | E15: 0.23111718 | F15: → | G15: Steady ~22-23%. Reflects efficient deployment of a large, cash-rich asset base — unusual for an asset-heavy FMCG company.
A16: Return on Capital Employed (ROCE) | B16: EBIT / (Total Assets − CL) | C16: 0.34813331 | D16: 0.35514631 | E16: 0.37663985 | F16: ↑ | G16: ROCE strengthening toward 39% — exceptional for any large-cap. Reflects extremely low debt, high EBIT, and efficient capital allocation.
A17: Return on Capital Invested (ROIC) | B17: NOPAT / (Equity + Net Debt) | C17: 0.29922308 | D17: 0.29462262 | E17: 0.30564518 | F17: → | G17: ROIC > 30% — significantly above cost of capital (estimated ~10-12%), creating enormous economic value. ITC is a sustained value creator.
A18: C. EFFICIENCY / ACTIVITY RATIOS
A19: Asset Turnover | B19: Revenue / Avg Total Assets | C19: 0.82139537 | D19: 0.90722781 | E19: 0.98869383 | F19: ↑ | G19: Low at 0.85–0.91x, reflecting large NC investments and treasury portfolio. Asset-light in operations but balance sheet heavy with financial assets.
A20: Fixed Asset Turnover | B20: Revenue / Avg Net Fixed Assets (PPE) | C20: 3.6479489 | D20: 4.0291445 | E20: 5.1526131 | F20: ↑ | G20: Improving from 3.65x to 5.16x: reflects the Hotels deconsolidation in FY25 (large fixed assets exited) and continued efficient utilisation of remaining PPE.
A21: Inventory Turnover | B21: Cost of Goods Sold / Avg Inventories | C21: 1.811373 | D21: 2.1469116 | E21: 1.9000225 | F21: ↓ | G21: Declining to 1.88x — inventory build (+19% YoY) outpaced cost growth. ITC is accumulating leaf tobacco and raw materials; could be strategic but bears monitoring.
A22: Inventory Days | B22: 365 / Inventory Turnover | C22: 201.5046 | D22: 170.01166 | E22: 192.10298 | F22: ↑ | G22: Rising from ~67 to ~76 to ~94 days. Significant inventory accumulation in FY26 warrants monitoring — whether strategic or demand-side risk.
A23: Debtors Turnover | B23: Revenue / Avg Trade Receivables | C23: 16.89818 | D23: 18.66397 | E23: 20.807178 | F23: ↑ | G23: Improved markedly to 20.9x in FY26 as trade receivables fell 17% even as revenues grew 10%. Strong collections management.
A24: Debtor Days (DSO) | B24: 365 / Debtors Turnover | C24: 21.59996 | D24: 19.556397 | E24: 17.542023 | F24: ↓ | G24: DSO improving to ~17 days — exceptional for a large FMCG company. Very low credit risk and strong channel discipline.
A25: Payable Turnover | B25: Purchases / Avg Trade Payables | C25: 5.6945757 | D25: 6.8097714 | E25: 6.7194111 | F25: → | G25: Stable at 6.8–7.0x — ITC pays creditors in ~52 days, reflecting a balanced supplier relationship policy.
A26: Creditor Days (DPO) | B26: 365 / Payable Turnover | C26: 64.096083 | D26: 53.599449 | E26: 54.320236 | F26: → | G26: ~52 days DPO: reasonable; ITC is not aggressively stretching payables (sign of supplier power balance).
A27: Cash Conversion Cycle | B27: Inventory Days + DSO − DPO | C27: 31.8 | D27: 44.1 | E27: 59.4 | F27: ↑ | G27: CCC rose from 31.8 to 59.4 days — primarily due to inventory build. Rising CCC implies more cash tied up in working capital; needs monitoring in FY27.
A28: D. SOLVENCY / LEVERAGE RATIOS
A29: Debt-to-Equity Ratio | B29: (NC Borrowings + Current Borrowings) / Total Equity | C29: 0.00015062097 | D29: 0.0012963448 | E29: 0.030000403 | F29: ↑ | G29: Spiked from near-zero to 0.030x — still virtually zero. The 23x jump in ST borrowings is notable in absolute terms but immaterial vs the equity base.
A30: Net Debt / EBITDA | B30: (Total Debt − Cash − Current Investments) / EBITDA | C30: -0.48498825 | D30: -0.58760402 | E30: -0.63769509 | F30: → | G30: Deeply negative net debt — ITC has net cash exceeding ₹19,000 Cr (excl bank deposits). Cash-rich balance sheet is a fortress. Net debt/EBITDA is meaningless (negative).
A31: Interest Coverage Ratio | B31: EBIT / Finance Costs | C31: 676.02634 | D31: 598.57967 | E31: 333.57121 | F31: ↓ | G31: Fell from 675x to 333x — still astronomically high. Finance costs doubled but remain immaterial. No debt-servicing risk whatsoever.
A32: Debt Service Coverage Ratio | B32: EBIT / (Finance Costs + Principal Repayments) | C32: 249.42821 | D32: 240.6066 | E32: 149.64583 | F32: ↓ | G32: Declining but still >150x. ITC can comfortably meet all debt obligations. Lease payments included in denominator.
A33: Equity Multiplier | B33: Total Assets / Total Equity | C33: 1.2261476 | D33: 1.2513247 | E33: 1.2870659 | F33: → | G33: Stable at ~1.28x — very low leverage multiplier, confirming the predominantly equity-funded capital structure.
A34: Total Debt Ratio | B34: Total Liabilities / Total Assets | C34: 0.18443753 | D34: 0.2008469 | E34: 0.22303901 | F34: ↑ | G34: Slightly rising from 18.4% to 20.0% to 22.3% — mainly due to current liability growth; still exceptionally low.
A35: Dividend Payout Ratio | B35: Dividends Paid / PAT Attributable to Owners | C35: 0.97264842 | D35: 0.51176819 | E35: 0.8831275 | F35: ↑ | G35: Payout ratio jumped to ~88% in FY26 — ITC distributes almost all earnings to shareholders. Very high dividend yield stock; limited retained earnings for reinvestment.

Sheet Financial Data
A1: ITC LIMITED — CONSOLIDATED FINANCIAL DATA (₹ in Crores)
A2: Item | B2: FY2024 | C2: FY2025 | D2: FY2026
A3: BALANCE SHEET — ASSETS
A4: Property, Plant & Equipment (Net) | B4: 23082.33 | C4: 17428.89 | D4: 17471.2
A5: Capital Work-in-Progress | B5: 2851.14 | C5: 1087.6 | D5: 1499.41
A6: Investment Property | B6: 340.93 | C6: 322.4 | D6: 303.36
A7: Goodwill | B7: 779.73 | C7: 896.93 | D7: 993.29
A8: Other Intangible Assets | B8: 2678.11 | C8: 2724.74 | D8: 3173.66
A9: Right-of-Use Assets | B9: 939.12 | C9: 581.89 | D9: 501.02
A10: Equity Method Investments | B10: 549.73 | C10: 4711.78 | D10: 5288.24
A11: NC Financial Assets — Investments | B11: 17619.87 | C11: 13720.54 | D11: 12089.55
A12: NC Financial Assets — Others | B12: 18032.91 | C12: 15285.71 | D12: 12437.64
A13: Deferred Tax Assets (Net) | B13: 72.19 | C13: 87.98 | D13: 155.18
A14: Other Non-Current Assets | B14: 1379.86 | C14: 1015.93 | D14: 1088.45
A15: TOTAL NON-CURRENT ASSETS | B15: 50760.62 | C15: 44197.4 | D15: 43083.97
... A26: TOTAL ASSETS | B26: 91826.16 | C26: 88090.68 | D26: 93792.38
A27: BALANCE SHEET — EQUITY & LIABILITIES
A28: Equity Share Capital | B28: 1248.47 | C28: 1251.41 | D28: 1252.95
A29: Other Equity | B29: 73258.53 | C29: 68778.64 | D29: 71254.35
A30: Non-Controlling Interests | B30: 382.97 | C30: 367.89 | D30: 365.72
A31: TOTAL EQUITY | B31: 74889.97 | C31: 70397.94 | D31: 72873.02
A32: NC Borrowings | B32: 1.76 | C32: 0 | D32: 60
A33: NC Lease Liabilities | B33: 230.61 | C33: 137.21 | D33: 140.86
A34: NC Other Financial Liabilities | B34: 433.96 | C34: 301.34 | D34: 510.4
A35: NC Provisions | B35: 288.3 | C35: 303.11 | D35: 389.43
A36: Deferred Tax Liabilities (Net) | B36: 2141.44 | C36: 2582.46 | D36: 3089.62
A37: Other NC Liabilities | B37: 149.72 | C37: 34.51 | D37: 41.78
A38: TOTAL NC LIABILITIES | B38: 3245.79 | C38: 3358.63 | D38: 4232.09
A39: Current Borrowings | B39: 9.52 | C39: 91.26 | D39: 2126.22
... A47: TOTAL EQUITY & LIABILITIES | B47: 91826.16 | C47: 88090.68 | D47: 93792.38
A48: PROFIT & LOSS STATEMENT
A49: Revenue from Operations | B49: 73891.43 | C49: 81612.78 | D49: 89913.33
A50: Other Income | B50: 2693.22 | C50: 2529.69 | D50: 2425.8
A51: TOTAL INCOME | B51: 76584.65 | C51: 84142.47 | D51: 92339.13
A52: Cost of Materials Consumed | B52: 21288.44 | C52: 23757.33 | D52: 26272.33
A53: Purchases of Stock-in-Trade | B53: 6060.13 | C53: 8947.04 | D53: 8826.01
A54: Changes in Inventories | B54: 367.77 | C54: 725.65 | D54: 2550.46
A55: Excise Duty | B55: 5959.49 | C55: 6289.44 | D55: 11044.93
A56: Employee Benefits Expense | B56: 5548.53 | C56: 6169.78 | D56: 6781.5
A57: Finance Costs | B57: 39.11 | C57: 45.06 | D57: 85.17
...

Sheet Comparative BS
A1: ITC LIMITED — Comparative Balance Sheet (₹ in Crores)
A2: Particulars | B2: FY2024 (₹ Cr) | C2: FY2025 (₹ Cr) | D2: FY2026 (₹ Cr) | E2: Change FY24→FY25 (₹ Cr) | F2: Change FY25→FY26 (₹ Cr)
A4: NON-CURRENT ASSETS
A5: Property, Plant and Equipment | B5: 23082.33 | C5: 17428.89 | D5: 17471.2 | E5: =C5-B5 -> -5653.44 | F5: =D5-C5 -> 42.31
A6: Capital Work-in-Progress | B6: 2851.14 | C6: 1087.6 | D6: 1499.41 | E6: =C6-B6 -> -1763.54 | F6: =D6-C6 -> 411.81
A7: Investment Property | B7: 340.93 | C7: 322.4 | D7: 303.36 | E7: =C7-B7 -> -18.53 | F7: =D7-C7 -> -19.04
A8: Goodwill | B8: 779.73 | C8: 896.93 | D8: 993.29 | E8: =C8-B8 -> 117.2 | F8: =D8-C8 -> 96.36
A9: Other Intangible Assets | B9: 2678.11 | C9: 2724.74 | D9: 3173.66 | E9: =C9-B9 -> 46.63 | F9: =D9-C9 -> 448.92
A10: Intangible Assets Under Development | B10: 9.64 | C10: 3.31 | D10: 102.47 | E10: =C10-B10 -> -6.33 | F10: =D10-C10 -> 99.16
A11: Right-of-use Assets | B11: 939.12 | C11: 581.89 | D11: 501.02 | E11: =C11-B11 -> -357.23 | F11: =D11-C11 -> -80.87
A12: Investments (Equity Method) | B12: 549.73 | C12: 4711.78 | D12: 5288.24 | E12: =C12-B12 -> 4162.05 | F12: =D12-C12 -> 576.46
A13: Non-current Financial Assets | B13: 18032.91 | C13: 15285.71 | D13: 12437.64 | E13: =C13-B13 -> -2747.2 | F13: =D13-C13 -> -2848.07
A14: Deferred Tax Assets (Net) | B14: 72.19 | C14: 87.98 | D14: 155.18 | E14: =C14-B14 -> 15.79 | F14: =D14-C14 -> 67.2
A15: Income Tax Assets (Net) | B15: 44.93 | C15: 50.24 | D15: 70.05 | E15: =C15-B15 -> 5.31 | F15: =D15-C15 -> 19.81
A16: Other Non-current Assets | B16: 1379.86 | C16: 1015.93 | D16: 1088.45 | E16: =C16-B16 -> -363.93 | F16: =D16-C16 -> 72.52
A17: Total Non-current Assets | B17: 50760.62 | C17: 44197.4 | D17: 43083.97 | E17: =C17-B17 -> -6563.22 | F17: =D17-C17 -> -1113.43
A18: CURRENT ASSETS
A19: Inventories | B19: 14152.88 | C19: 15637.56 | D19: 18622.96 | E19: =C19-B19 -> 1484.68 | F19: =D19-C19 -> 2985.4
A20: Biological Assets | B20: 150 | C20: 198.58 | D20: 249.69 | E20: =C20-B20 -> 48.58 | F20: =D20-C20 -> 51.11
A21: Current Investments | B21: 12944.42 | C21: 16287.5 | D21: 20750.64 | E21: =C21-B21 -> 3343.08 | F21: =D21-C21 -> 4463.14
A22: Trade Receivables | B22: 4025.82 | C22: 4719.67 | D22: 3922.86 | E22: =C22-B22 -> 693.85 | F22: =D22-C22 -> -796.81
A23: Cash and Cash Equivalents | B23: 625.89 | C23: 620 | D23: 643.46 | E23: =C23-B23 -> -5.89 | F23: =D23-C23 -> 23.46
A24: Bank Balances (Other) | B24: 6591.79 | C24: 3392.36 | D24: 2365.33 | E24: =C24-B24 -> -3199.43 | F24: =D24-C24 -> -1027.03
A25: Current Loans | B25: 9.81 | C25: 9.51 | D25: 8.52 | E25: =C25-B25 -> -0.3 | F25: =D25-C25 -> -0.99
A26: Other Current Financial Assets | B26: 1181.74 | C26: 1662.32 | D26: 2361.34 | E26: =C26-B26 -> 480.58 | F26: =D26-C26 -> 699.02
A27: Other Current Assets | B27: 1383.19 | C27: 1371.85 | D27: 1783.61 | E27: =C27-B27 -> -11.34 | F27: =D27-C27 -> 411.76
A28: Total Current Assets | B28: 41065.54 | C28: 43893.28 | D28: 50708.41 | E28: =C28-B28 -> 2827.74 | F28: =D28-C28 -> 6815.13
A29: TOTAL ASSETS | B29: 91826.16 | C29: 88090.68 | D29: 93792.38 | E29: =C29-B29 -> -3735.48 | F29: =D29-C29 -> 5701.7
A30: EQUITY
A31: Equity Share Capital | B31: 1248.47 | C31: 1251.41 | D31: 1252.95 | E31: =C31-B31 -> 2.94 | F31: =D31-C31 -> 1.54
A32: Other Equity | B32: 73258.53 | C32: 68778.64 | D32: 71254.35 | E32: =C32-B32 -> -4479.89 | F32: =D32-C32 -> 2475.71
A33: Equity Attr. to Owners of Parent | B33: 74507 | C33: 70030.05 | D33: 72507.3 | E33: =C33-B33 -> -4476.95 | F33: =D33-C33 -> 2477.25
A34: Non-controlling Interests | B34: 382.97 | C34: 367.89 | D34: 365.72 | E34: =C34-B34 -> -15.08 | F34: =D34-C34 -> -2.17
A35: Total Equity | B35: 74889.97 | C35: 70397.94 | D35: 72873.02 | E35: =C35-B35 -> -4492.03 | F35: =D35-C35 -> 2475.08
A36: NON-CURRENT LIABILITIES
A37: Non-current Borrowings | B37: 1.76 | C37: 0 | D37: 60 | E37: =C37-B37 -> -1.76 | F37: =D37-C37 -> 60
A38: Lease Liabilities (NC) | B38: 230.61 | C38: 137.21 | D38: 140.86 | E38: =C38-B38 -> -93.4 | F38: =D38-C38 -> 3.65
A39: Other NC Financial Liabilities | B39: 433.96 | C39: 301.34 | D39: 510.4 | E39: =C39-B39 -> -132.62 | F39: =D39-C39 -> 209.06
A40: Provisions (NC) | B40: 288.3 | C40: 303.11 | D40: 389.43 | E40: =C40-B40 -> 14.81 | F40: =D40-C40 -> 86.32
A41: Deferred Tax Liabilities (Net) | B41: 2141.44 | C41: 2582.46 | D41: 3089.62 | E41: =C41-B41 -> 441.02 | F41: =D41-C41 -> 507.16
...

Sheet Comparative P&L
A1: ITC LIMITED — Comparative Statement of Profit & Loss (₹ in Crores)
A2: Particulars | B2: FY2024 (₹ Cr) | C2: FY2025 (₹ Cr) | D2: FY2026 (₹ Cr) | E2: Change FY24→FY25 (₹ Cr) | F2: Change FY25→FY26 (₹ Cr)
A4: INCOME
A5: Revenue from Operations | B5: 73891.43 | C5: 81612.78 | D5: 89913.33 | E5: =C5-B5 -> 7721.35 | F5: =D5-C5 -> 8300.55
A6: Other Income | B6: 2693.22 | C6: 2529.69 | D6: 2425.8 | E6: =C6-B6 -> -163.53 | F6: =D6-C6 -> -103.89
A7: Total Income | B7: 76584.65 | C7: 84142.47 | D7: 92339.13 | E7: =C7-B7 -> 7557.82 | F7: =D7-C7 -> 8196.66
A8: EXPENSES
A9: Cost of Materials Consumed | B9: 21288.44 | C9: 23757.33 | D9: 26272.33 | E9: =C9-B9 -> 2468.89 | F9: =D9-C9 -> 2515
A10: Purchases of Stock-in-Trade & Bio. Assets | B10: 6060.13 | C10: 8947.04 | D10: 8826.01 | E10: =C10-B10 -> 2886.91 | F10: =D10-C10 -> -121.03
A11: Changes in Inventories | B11: -367.77 | C11: -725.65 | D11: -2550.46 | E11: =C11-B11 -> -357.88 | F11: =D11-C11 -> -1824.81
A12: Excise Duty | B12: 5959.49 | C12: 6289.44 | D12: 11044.93 | E12: =C12-B12 -> 329.95 | F12: =D12-C12 -> 4755.49
A13: Employee Benefits Expense | B13: 5548.53 | C13: 6169.78 | D13: 6781.5 | E13: =C13-B13 -> 621.25 | F13: =D13-C13 -> 611.72
A14: Finance Costs | B14: 39.11 | C14: 45.06 | D14: 85.17 | E14: =C14-B14 -> 5.95 | F14: =D14-C14 -> 40.11
A15: Depreciation & Amortisation | B15: 1518.05 | C15: 1646.32 | D15: 1710.53 | E15: =C15-B15 -> 128.27 | F15: =D15-C15 -> 64.21
A16: Other Expenses | B16: 10152.82 | C16: 11196.63 | D16: 12221.11 | E16: =C16-B16 -> 1043.81 | F16: =D16-C16 -> 1024.48
A17: Total Expenses | B17: 50198.8 | C17: 57325.95 | D17: 64391.12 | E17: =C17-B17 -> 7127.15 | F17: =D17-C17 -> 7065.17
A18: Share of Profit of Associates & JVs | B18: 14.43 | C18: 110.42 | D18: 377.08 | E18: =C18-B18 -> 95.99 | F18: =D18-C18 -> 266.66
A19: Profit Before Exceptional Items & Tax | B19: 26400.28 | C19: 26926.94 | D19: 28325.09 | E19: =C19-B19 -> 526.66 | F19: =D19-C19 -> 1398.15
A20: Exceptional Items | B20: 0 | C20: 0 | D20: -291.7 | E20: =C20-B20 -> 0 | F20: =D20-C20 -> -291.7
... A28: Total Comprehensive Income | B28: 23707.02 | C28: 34427.62 | D28: 20374.86 | E28: =C28-B28 -> 10720.6 | F28: =D28-C28 -> -14052.76
A30: Note: All figures in ₹ Crores. Source: ITC Consolidated Annual Reports FY2024, FY2025, FY2026.

Sheet Common-Size BS
A1: ITC LIMITED — Common-Size Balance Sheet (% of Total Assets)
A2: Particulars | B2: FY2024 (₹ Cr) | C2: FY2024 (%) | D2: FY2025 (₹ Cr) | E2: FY2025 (%) | F2: FY2026 (₹ Cr) | G2: FY2026 (%)
A4: NON-CURRENT ASSETS
A5: Property, Plant and Equipment | B5: 23082.33 | C5: =B5/B29 -> 0.25136987 | D5: 17428.89 | E5: =D5/D29 -> 0.19785169 | F5: 17471.2 | G5: =F5/F29 -> 0.18627526
A6: Capital Work-in-Progress | B6: 2851.14 | C6: =B6/B29 -> 0.031049322 | D6: 1087.6 | E6: =D6/D29 -> 0.012346369 | F6: 1499.41 | G6: =F6/F29 -> 0.01598648
A7: Investment Property | B7: 340.93 | C7: =B7/B29 -> 0.0037127764 | D7: 322.4 | E7: =D7/D29 -> 0.003659865 | F7: 303.36 | G7: =F7/F29 -> 0.0032343779
A8: Goodwill | B8: 779.73 | C8: =B8/B29 -> 0.0084913711 | D8: 896.93 | E8: =D8/D29 -> 0.010181894 | F8: 993.29 | G8: =F8/F29 -> 0.010590306
A9: Other Intangible Assets | B9: 2678.11 | C9: =B9/B29 -> 0.029165 | D9: 2724.74 | E9: =D9/D29 -> 0.030931081 | F9: 3173.66 | G9: =F9/F29 -> 0.033837077
A10: Intangible Assets Under Development | B10: 9.64 | C10: =B10/B29 -> 0.00010498098 | D10: 3.31 | E10: =D10/D29 -> 3.7574917e-05 | F10: 102.47 | G10: =F10/F29 -> 0.0010925195
A11: Right-of-use Assets | B11: 939.12 | C11: =B11/B29 -> 0.010227151 | D11: 581.89 | E11: =D11/D29 -> 0.0066055796 | F11: 501.02 | G11: =F11/F29 -> 0.0053417986
A12: Investments (Equity Method) | B12: 549.73 | C12: =B12/B29 -> 0.0059866382 | D12: 4711.78 | E12: =D12/D29 -> 0.053487838 | F12: 5288.24 | G12: =F12/F29 -> 0.056382405
A13: Non-current Financial Assets | B13: 18032.91 | C13: =B13/B29 -> 0.19638097 | D13: 15285.71 | E13: =D13/D29 -> 0.17352244 | F13: 12437.64 | G13: =F13/F29 -> 0.13260821
A14: Deferred Tax Assets (Net) | B14: 72.19 | C14: =B14/B29 -> 0.00078615941 | D14: 87.98 | E14: =D14/D29 -> 0.00099874357 | F14: 155.18 | G14: =F14/F29 -> 0.0016545054
A15: Income Tax Assets (Net) | B15: 44.93 | C15: =B15/B29 -> 0.00048929412 | D15: 50.24 | E15: =D15/D29 -> 0.0005703214 | F15: 70.05 | G15: =F15/F29 -> 0.00074686238
A16: Other Non-current Assets | B16: 1379.86 | C16: =B16/B29 -> 0.015026873 | D16: 1015.93 | E16: =D16/D29 -> 0.011532775 | F16: 1088.45 | G16: =F16/F29 -> 0.011604887
A17: Total Non-current Assets | B17: 50760.62 | C17: =B17/B29 -> 0.5527904 | D17: 44197.4 | E17: =D17/D29 -> 0.50172618 | F17: 43083.97 | G17: =F17/F29 -> 0.45935469
A18: CURRENT ASSETS
A19: Inventories | B19: 14152.88 | C19: =B19/B29 -> 0.15412688 | D19: 15637.56 | E19: =D19/D29 -> 0.17751662 | F19: 18622.96 | G19: =F19/F29 -> 0.19855515
A20: Biological Assets | B20: 150 | C20: =B20/B29 -> 0.0016335214 | D20: 198.58 | E20: =D20/D29 -> 0.002254268 | F20: 249.69 | G20: =F20/F29 -> 0.0026621566
A21: Current Investments | B21: 12944.42 | C21: =B21/B29 -> 0.14096658 | D21: 16287.5 | E21: =D21/D29 -> 0.1848947 | F21: 20750.64 | G21: =F21/F29 -> 0.22124015
A22: Trade Receivables | B22: 4025.82 | C22: =B22/B29 -> 0.043841755 | D22: 4719.67 | E22: =D22/D29 -> 0.053577405 | F22: 3922.86 | G22: =F22/F29 -> 0.041824933
A23: Cash and Cash Equivalents | B23: 625.89 | C23: =B23/B29 -> 0.0068160315 | D23: 620 | E23: =D23/D29 -> 0.007038202 | F23: 643.46 | G23: =F23/F29 -> 0.006860472
A24: Bank Balances (Other) | B24: 6591.79 | C24: =B24/B29 -> 0.071785535 | D24: 3392.36 | E24: =D24/D29 -> 0.038509863 | F24: 2365.33 | G24: =F24/F29 -> 0.025218786
A25: Current Loans | B25: 9.81 | C25: =B25/B29 -> 0.0001068323 | D25: 9.51 | E25: =D25/D29 -> 0.00010795694 | F25: 8.52 | G25: =F25/F29 -> 9.0838936e-05
A26: Other Current Financial Assets | B26: 1181.74 | C26: =B26/B29 -> 0.012869317 | D26: 1662.32 | E26: =D26/D29 -> 0.018870555 | F26: 2361.34 | G26: =F26/F29 -> 0.025176246
A27: Other Current Assets | B27: 1383.19 | C27: =B27/B29 -> 0.015063137 | D27: 1371.85 | E27: =D27/D29 -> 0.015573157 | F27: 1783.61 | G27: =F27/F29 -> 0.019016577
A28: Total Current Assets | B28: 41065.54 | C28: =B28/B29 -> 0.4472096 | D28: 43893.28 | E28: =D28/D29 -> 0.49827382 | F28: 50708.41 | G28: =F28/F29 -> 0.54064531
A29: TOTAL ASSETS | B29: 91826.16 | C29: =B29/B29 -> 1 | D29: 88090.68 | E29: =D29/D29 -> 1 | F29: 93792.38 | G29: =F29/F29 -> 1
A30: EQUITY
A31: Equity Share Capital | B31: 1248.47 | C31: =B31/B29 -> 0.013596017 | D31: 1251.41 | E31: =D31/D29 -> 0.01420593 | F31: 1252.95 | G31: =F31/F29 -> 0.013358761
A32: Other Equity | B32: 73258.53 | C32: =B32/B29 -> 0.79779586 | D32: 68778.64 | E32: =D32/D29 -> 0.78077091 | F32: 71254.35 | G32: =F32/F29 -> 0.75970297
A33: Equity Attr. to Owners of Parent | B33: 74507 | C33: =B33/B29 -> 0.81139187 | D33: 70030.05 | E33: =D33/D29 -> 0.79497684 | F33: 72507.3 | G33: =F33/F29 -> 0.77306173
A34: Non-controlling Interests | B34: 382.97 | C34: =B34/B29 -> 0.004170598 | D34: 367.89 | E34: =D34/D29 -> 0.0041762647 | F34: 365.72 | G34: =F34/F29 -> 0.0038992507
A35: Total Equity | B35: 74889.97 | C35: =B35/B29 -> 0.81556247 | D35: 70397.94 | E35: =D35/D29 -> 0.7991531 | F35: 72873.02 | G35: =F35/F29 -> 0.77696099
A36: NON-CURRENT LIABILITIES
A37: Non-current Borrowings | B37: 1.76 | C37: =B37/B29 -> 1.9166651e-05 | D37: 0 | F37: 60 | G37: =F37/F29 -> 0.00063971082
A38: Lease Liabilities (NC) | B38: 230.61 | C38: =B38/B29 -> 0.0025113758 | D38: 137.21 | E38: =D38/D29 -> 0.0015575995 | F38: 140.86 | G38: =F38/F29 -> 0.0015018278
A39: Other NC Financial Liabilities | B39: 433.96 | C39: =B39/B29 -> 0.0047258864 | D39: 301.34 | E39: =D39/D29 -> 0.0034207932 | F39: 510.4 | G39: =F39/F29 -> 0.0054418067
A40: Provisions (NC) | B40: 288.3 | C40: =B40/B29 -> 0.0031396282 | D40: 303.11 | E40: =D40/D29 -> 0.0034408861 | F40: 389.43 | G40: =F40/F29 -> 0.0041520431
A41: Deferred Tax Liabilities (Net) | B41: 2141.44 | C41: =B41/B29 -> 0.023320588 | D41: 2582.46 | E41: =D41/D29 -> 0.029315928 | F41: 3089.62 | G41: =F41/F29 -> 0.032941056
...

Sheet Common-Size P&L
A1: ITC LIMITED — Common-Size Statement of Profit & Loss (% of Total Income)
A2: Particulars | B2: FY2024 (₹ Cr) | C2: FY2024 (%) | D2: FY2025 (₹ Cr) | E2: FY2025 (%) | F2: FY2026 (₹ Cr) | G2: FY2026 (%)
A4: INCOME
A5: Revenue from Operations | B5: 73891.43 | C5: =B5/B7 -> 0.96483342 | D5: 81612.78 | E5: =D5/D7 -> 0.96993563 | F5: 89913.33 | G5: =F5/F7 -> 0.97372945
A6: Other Income | B6: 2693.22 | C6: =B6/B7 -> 0.035166577 | D6: 2529.69 | E6: =D6/D7 -> 0.030064366 | F6: 2425.8 | G6: =F6/F7 -> 0.026270553
A7: Total Income | B7: 76584.65 | C7: =B7/B7 -> 1 | D7: 84142.47 | E7: =D7/D7 -> 1 | F7: 92339.13 | G7: =F7/F7 -> 1
A8: EXPENSES
A9: Cost of Materials Consumed | B9: 21288.44 | C9: =B9/B7 -> 0.27797267 | D9: 23757.33 | E9: =D9/D7 -> 0.28234648 | F9: 26272.33 | G9: =F9/F7 -> 0.28452001
A10: Purchases of Stock-in-Trade & Bio. Assets | B10: 6060.13 | C10: =B10/B7 -> 0.079129826 | D10: 8947.04 | E10: =D10/D7 -> 0.10633203 | F10: 8826.01 | G10: =F10/F7 -> 0.095582555
A11: Changes in Inventories | B11: -367.77 | C11: =B11/B7 -> -0.0048021372 | D11: -725.65 | E11: =D11/D7 -> -0.0086240634 | F11: -2550.46 | G11: =F11/F7 -> -0.027620576
A12: Excise Duty | B12: 5959.49 | C12: =B12/B7 -> 0.077815724 | D12: 6289.44 | E12: =D12/D7 -> 0.074747509 | F12: 11044.93 | G12: =F12/F7 -> 0.11961267
A13: Employee Benefits Expense | B13: 5548.53 | C13: =B13/B7 -> 0.072449636 | D13: 6169.78 | E13: =D13/D7 -> 0.073325397 | F13: 6781.5 | G13: =F13/F7 -> 0.073441238
A14: Finance Costs | B14: 39.11 | C14: =B14/B7 -> 0.00051067675 | D14: 45.06 | E14: =D14/D7 -> 0.00053552029 | F14: 85.17 | G14: =F14/F7 -> 0.00092236087
A15: Depreciation & Amortisation | B15: 1518.05 | C15: =B15/B7 -> 0.019821857 | D15: 1646.32 | E15: =D15/D7 -> 0.019565863 | F15: 1710.53 | G15: =F15/F7 -> 0.018524433
A16: Other Expenses | B16: 10152.82 | C16: =B16/B7 -> 0.13256991 | D16: 11196.63 | E16: =D16/D7 -> 0.13306752 | F16: 12221.11 | G16: =F16/F7 -> 0.13235028
A17: Total Expenses | B17: 50198.8 | C17: =B17/B7 -> 0.65546816 | D17: 57325.95 | E17: =D17/D7 -> 0.68129626 | F17: 64391.12 | G17: =F17/F7 -> 0.69733297
A18: Share of Profit of Associates & JVs | B18: 14.43 | C18: =B18/B7 -> 0.00018841896 | D18: 110.42 | E18: =D18/D7 -> 0.0013122981 | F18: 377.08 | G18: =F18/F7 -> 0.0040836425
A19: Profit Before Exceptional Items & Tax | B19: 26400.28 | C19: =B19/B7 -> 0.34472025 | D19: 26926.94 | E19: =D19/D7 -> 0.32001604 | F19: 28325.09 | G19: =F19/F7 -> 0.30675067
A20: Exceptional Items | B20: 0 | C20: =B20/B7 -> 0 | D20: 0 | E20: =D20/D7 -> 0 | F20: -291.7 | G20: =F20/F7 -> -0.0031590075
A21: Profit Before Tax (Continuing Ops) | B21: 26400.28 | C21: =B21/B7 -> 0.34472025 | D21: 26926.94 | E21: =D21/D7 -> 0.32001604 | F21: 28033.39 | G21: =F21/F7 -> 0.30359166
A22: Current Tax | B22: 6017.21 | C22: =B22/B7 -> 0.0785694 | D22: 6509.61 | E22: =D22/D7 -> 0.077364142 | F22: 6412.97 | G22: =F22/F7 -> 0.069450189
A23: Deferred Tax | B23: 192.25 | C23: =B23/B7 -> 0.0025102942 | D23: 380.86 | E23: =D23/D7 -> 0.0045263706 | F23: 602.27 | G23: =F23/F7 -> 0.0065223703
A24: Profit for Year (Continuing Ops) | B24: 20190.82 | C24: =B24/B7 -> 0.26364056 | D24: 20036.47 | E24: =D24/D7 -> 0.23812553 | F24: 21018.15 | G24: =F24/F7 -> 0.2276191
A25: Profit from Discontinued Operations (Net) | B25: 560.54 | C25: =B25/B7 -> 0.0073192213 | D25: 15016.01 | E25: =D25/D7 -> 0.17845934 | F25: 0 | G25: =F25/F7 -> 0
A26: Profit for the Year | B26: 20751.36 | C26: =B26/B7 -> 0.27095978 | D26: 35052.48 | E26: =D26/D7 -> 0.41658487 | F26: 21018.15 | G26: =F26/F7 -> 0.2276191
A27: Other Comprehensive Income (Net) | B27: 2955.66 | C27: =B27/B7 -> 0.038593373 | D27: -624.86 | E27: =D27/D7 -> -0.0074262141 | F27: -643.29 | G27: =F27/F7 -> -0.0069666023
A28: Total Comprehensive Income | B28: 23707.02 | C28: =B28/B7 -> 0.30955315 | D28: 34427.62 | E28: =D28/D7 -> 0.40915866 | F28: 20374.86 | G28: =F28/F7 -> 0.2206525
A30: Note: % calculated as proportion of Total Income (Revenue from Ops + Other Income). Source: ITC Consolidated Annual Reports.

Sheet Trend Analysis
A1: ITC LIMITED — Trend Analysis (Base Year = FY2024, Index = 100)
A2: Key Indicator | B2: FY2024 (Base = 100) | C2: FY2025 Index | D2: FY2026 Index | E2: YoY % Change (FY25→FY26)
A4: ── BALANCE SHEET ──
A5: Total Assets | B5: 100 | C5: 95.93 | D5: 102.14 | E5: 6.47
A6: Total Equity | B6: 100 | C6: 94 | D6: 97.31 | E6: 3.52
A7: Total Non-current Assets | B7: 100 | C7: 87.07 | D7: 84.88 | E7: -2.52
A8: Total Current Assets | B8: 100 | C8: 106.89 | D8: 123.48 | E8: 15.53
A9: Inventories | B9: 100 | C9: 110.49 | D9: 131.58 | E9: 19.09
A10: Current Investments | B10: 100 | C10: 125.83 | D10: 160.31 | E10: 27.4
A11: Total NCL | B11: 100 | C11: 103.48 | D11: 130.39 | E11: 26.01
A12: Total Current Liabilities | B12: 100 | C12: 104.7 | D12: 121.89 | E12: 16.42
A13: Property, Plant & Equipment | B13: 100 | C13: 75.51 | D13: 75.69 | E13: 0.24
A14: ── PROFIT & LOSS ──
A15: Revenue from Operations | B15: 100 | C15: 110.45 | D15: 121.68 | E15: 10.17
A16: Total Income | B16: 100 | C16: 109.87 | D16: 120.57 | E16: 9.74
A17: Total Expenses | B17: 100 | C17: 114.2 | D17: 128.27 | E17: 12.32
A18: EBIT (PBT + Finance Costs) | B18: 100 | C18: 102.01 | D18: 106.35 | E18: 4.25
A19: Profit Before Tax | B19: 100 | C19: 101.99 | D19: 106.19 | E19: 4.11
A20: Profit for the Year | B20: 100 | C20: 168.92 | D20: 101.29 | E20: -40.04
A21: Employee Benefits Expense | B21: 100 | C21: 111.2 | D21: 122.22 | E21: 9.91
A22: Finance Costs | B22: 100 | C22: 115.21 | D22: 217.77 | E22: 89.01
A23: ── KEY RATIOS ──
A24: Net Profit Margin (%) | B24: 100 | C24: 153.74 | D24: 84 | E24: -45.36
A25: Return on Equity (%) | B25: 100 | C25: 179.69 | D25: 104.09 | E25: -42.07
A26: Current Ratio (x) | B26: 2.9996 | C26: 3.0622 | D26: 3.0387 | E26: -0.76
A27: Asset Turnover (x) | B27: 0.8047 | C27: 0.9265 | D27: 0.9586 | E27: 3.47
A28: Debt-to-Equity (x) | B28: 0.2261 | C28: 0.2513 | D28: 0.2871 | E28: 14.22
A29: Revenue/Employee Exp (x) | B29: 13.3173 | C29: 13.2278 | D29: 13.2586 | E29: 0.23
A31: Note: Index values calculated as (Current Year Value / FY2024 Base Value) × 100. Ratios are actuals, not indexed.

Sheet Interpretation
A1: ITC LIMITED — Financial Analysis: Key Observations & Interpretation (FY2024–FY2026)
A3: COMPARATIVE BALANCE SHEET
A4: 1. Total Assets
A5: Trend | B5: Total Assets declined from ₹91,826 Cr (FY24) to ₹88,091 Cr (FY25) — a fall of ~4.1% — before recovering to ₹93,792 Cr in FY26 (+6.5%). The FY25 dip was driven by a large reduction in PP&E (₹23,082 Cr → ₹17,429 Cr), likely reflecting block disposals or impairments tied to the Hotels demerger.
A6: 2. Equity Erosion (FY25) & Recovery (FY26) | B6: Total Equity fell from ₹74,890 Cr (FY24) to ₹70,398 Cr (FY25), a drop of ~6%, primarily due to a sharp reduction in Other Equity (₹73,259 Cr → ₹68,779 Cr). This suggests dividend payouts and/or buybacks exceeded retained profits in FY25. In FY26 equity partially recovered to ₹72,873 Cr.
A7: 3. Asset Mix Shift: NCA vs CA | B7: Non-current Assets shrank from ₹50,761 Cr to ₹44,197 Cr (FY25) and further to ₹43,084 Cr (FY26), while Current Assets expanded from ₹41,066 Cr to ₹43,893 Cr to ₹50,708 Cr. The rising share of current assets (from 44.7% to 54.1% of Total Assets) points to higher working capital intensity and growing liquid investments.
A8: 4. Surge in Current Investments (FY26) | B8: Current Investments jumped from ₹12,944 Cr (FY24) to ₹20,751 Cr (FY26) — a 60% rise — showing ITC is parking significant surplus cash in liquid mutual funds/bonds rather than deploying it in capex or M&A.
A9: 5. Borrowings Nearly Zero | B9: ITC is virtually debt-free. Total borrowings (current + non-current) were just ₹2,186 Cr in FY26 (vs ₹11.28 Cr in FY24), placing it in an extremely low-leverage position. Finance costs have risen sharply (₹39 Cr → ₹85 Cr) but remain negligible relative to earnings.
A10: COMPARATIVE P&L
A11: 6. Robust Revenue Growth | B11: Revenue from Operations grew at a healthy CAGR of ~10.2% over FY24–FY26: ₹73,891 Cr → ₹81,613 Cr → ₹89,913 Cr. This reflects volume and value growth across FMCG, Agribusiness, and Paperboards segments even as the Hotels business was demerged.
A12: 7. Rising Cost Pressure (Total Expenses) | B12: Total Expenses grew faster than revenue: from ₹50,199 Cr (65.5% of income) to ₹64,391 Cr (69.7% of income) in FY26. Material costs (₹26,272 Cr, excl. purchase of stock-in-trade: ₹8,826 Cr) and Excise Duty (₹11,045 Cr) are the dominant drivers. Operating leverage is being compressed.
A13: 8. PAT Anomaly in FY25 | B13: Profit for the Year spiked to ₹35,052 Cr in FY25 from ₹20,751 Cr in FY24 due to exceptional profits from discontinued operations (Hotels demerger: ₹15,128 Cr exceptional income, net of tax). FY26 PAT normalised to ₹21,018 Cr — broadly in line with FY24, underscoring the one-time nature of the FY25 gain.
A14: 9. Profit Before Tax (Continuing Ops) — Steady Growth | B14: PBT from continuing operations grew steadily: ₹26,400 Cr → ₹26,927 Cr → ₹28,033 Cr. This indicates core business profitability is intact and growing at ~3% CAGR, though slower than revenue growth due to cost inflation.
A15: 10. Finance Cost Spike (FY26) | B15: Finance costs nearly doubled from ₹45 Cr (FY25) to ₹85 Cr (FY26), largely due to the ₹2,126 Cr in current borrowings (vs ₹91 Cr in FY25). Still immaterial relative to earnings, but worth monitoring.
A16: COMMON-SIZE ANALYSIS
A17: 11. Declining Material Cost % (as % Total Income) | B17: Material cost (consumed) as a % of Total Income rose from 27.8% to 28.5% — a 70 bps adverse movement. However, Purchases of Stock-in-Trade fell from 7.9% to 9.6% in FY25 and then to 9.6% in FY26, partly offset by inventory buildup (negative change-in-inventory ₹2,550 Cr in FY26 = stock accumulation).
A18: 12. Excise Duty Weight Rising | B18: Excise duty jumped from 7.8% (FY24) to 11.9% (FY26) of Total Income — a structural headwind for the cigarettes business, reflecting government policy. This compresses PAT margins when not fully passed on.
A19: 13. Employee Cost Stable at ~7% | B19: Employee benefit expense remained roughly stable at 7.3% of Total Income across all three years, indicating good productivity management despite inflationary pressures on salaries.
A20: 14. Equity Dominant Financing (>77%) | B20: Common-size BS shows Equity at 77.7% of Total Assets in FY26 (down from 81.5% in FY24), confirming ITC's conservative capital structure. Debt is under 3% of the balance sheet — a company almost entirely financed by its own profits.
A21: TREND ANALYSIS
A22: 15. Revenue Index FY26 = ~122 (Base FY24 = 100) | B22: Revenue has grown strongly — +21.7% over two years. Expenses grew at an even faster clip (index ~128), compressing operating margins. Net profit index (FY26 = ~101) confirms normalised profitability is back to FY24 levels post the Hotels windfall in FY25.
A23: 16. Current Ratio Improving | B23: Current ratio improved from 3.00x (FY24) to 3.06x (FY25) to 3.04x (FY26) — well above the safety threshold of 1.5x. Reflects strong liquidity with substantial liquid investments in current assets.
A24: 17. Asset Turnover Inching Up | B24: Asset turnover improved from 0.80x to 0.93x to 0.96x, meaning ITC is generating more revenue per rupee of assets deployed — a positive efficiency signal. As the Hotels segment (capital-heavy, lower turnover) is now demerged, this metric should continue to improve.
A25: 18. Net Profit Margin Compressed | B25: Net Profit Margin (PAT/Total Income) normalised to 22.8% in FY26 (FY24: 27.1%, FY25: 41.7% due to Hotels exceptional). The FY24 baseline margin itself is under pressure in FY26 — 22.8% vs 27.1% — due to rising excise duty and material costs. This is the most important watch metric.
A26: 19. Finance Cost Rising — Still Negligible | B26: Finance costs index jumped to 218 (FY26 vs FY24 base), but at ₹85 Cr it represents just 0.09% of revenue. Not yet a concern, but signals the company has taken on some short-term working capital borrowings in FY26 — likely to fund inventory build (₹18,623 Cr vs ₹14,153 Cr in FY24).
A27: OVERALL CONCLUSION
A28: Summary | B28: ITC remains one of India's most financially robust consumer goods conglomerates. Revenue growth is strong and consistent. The Hotels demerger in FY25 was value-accretive and has freed up capital. The company is cash-rich, nearly debt-free, and generating strong free cash flows deployed into liquid investments. Key risks to watch: (a) rising excise duty on cigarettes compressing FMCG margins, (b) material cost inflation, and (c) still-modest FMCG profitability beyond the cigarettes engine. The normalisation of PAT in FY26 is expected and does not signal structural weakness — the FY25 spike was a one-time demerger gain.
A30: Prepared by: Financial Analysis | Source: ITC Consolidated Annual Reports FY2024, FY2025, FY2026

Sheet Cover (2)
B3: ITC Limited — Comparable Company Analysis (CCA)
B4: Method 2 Valuation — Financial Statement Analysis Project
B6: Prepared per Project Guidelines Section 6, Method 2: implied valuation using EV/EBITDA, EV/EBIT, P/E and EV/Revenue multiples across a 4-company peer group.
B9: Company Valued | C9: ITC Limited (NSE: ITC | BSE: 500875)
B11: Peer Group (4 companies) | C11: Hindustan Unilever Ltd. · Godfrey Phillips India Ltd. · Nestlé India Ltd. · Britannia Industries Ltd.
B13: Basis | C13: FY2025-26 (year ended 31 March 2026) reported financials; market data as of August 2026
B15: Currency / Units | C15: ₹ Crore unless stated otherwise
B17: Source | C17: Company FY26 results releases, Screener.in, and other public filings/press coverage — see Sources tab for line-by-line citations
B20: Tab Guide
B22: Peer Data | C22: Raw inputs for ITC and each of the 4 peers: Revenue, EBITDA, EBIT, Net Income, Market Cap, Net Debt, Enterprise Value, EPS — with source and as-of date for every line.
B23: CCA Multiples | C23: EV/Revenue, EV/EBITDA, EV/EBIT and P/E computed for every company; Mean / Median / Min / Max computed across the 4-peer group only.
B24: Implied Valuation | C24: Peer multiples applied to ITC's own metrics to derive an implied Enterprise Value and implied price per share under each multiple and statistic — the ‘football field’ valuation range.
B25: Sources & Notes | C25: Full citation log and every simplifying assumption made, in the same spirit as the Assumptions Log in the companion DCF workbook.
B28: Colour convention: BLUE = hardcoded input/source data · BLACK = formula · GREEN = cross-sheet link.
B30: Academic exercise — not investment advice. Market data reflects a point-in-time snapshot (August 2026) compiled from public secondary sources; refresh before relying on it for any live decision.

Sheet Peer Data
B2: Peer Data — Inputs
B3: All figures ₹ Crore unless stated. FY2025-26 (year ended 31 March 2026) reported financials; market data as of August 2026.
B5: Company | C5: Revenue | D5: EBITDA | E5: EBIT | F5: Net Income | G5: Total Debt | H5: Cash & Investments | I5: Shares O/S (Cr) | J5: Share Price (₹) | K5: Market Cap | L5: Net Debt | M5: Enterprise Value | N5: EPS (₹) | O5: Data As Of | P5: Source
B6: ITC Limited (for reference) | C6: 89913.33 | D6: 27317.91 | E6: 25607.38 | F6: 21018.15 | G6: 2186.22 | H6: 21394.1 | I6: 1252.95 | J6: 278 | K6: =I6*J6 -> 348320.1 | L6: =G6-H6 -> -19207.88 | M6: =K6+L6 -> 329112.22 | N6: =F6/I6 -> 16.774931 | O6: Aug 2026 | P6: Company FY26 Report & Accounts; NSE/BSE closing price ~₹278 (Aug 2026), consistent with Sections 6.5/8 of the FSA report.
B7: Hindustan Unilever Ltd. | C7: 63763 | D7: 15054 | E7: 13721 | F7: 10652 | G7: 14 | H7: 8250 | I7: 234.98 | J7: =K7/I7 -> 2055.9154 | K7: 483099 | L7: =G7-H7 -> -8236 | M7: =K7+L7 -> 474863 | N7: =F7/I7 -> 45.331518 | O7: Aug 2026 | P7: HUL FY26 results release (turnover ₹63,763 Cr, EBITDA ₹15,054 Cr, D&A ₹1,333 Cr, PAT ₹10,652 Cr); Market Cap ₹4,83,099 Cr per Screener.in (Aug 2026); Total Debt/Cash per Simply Wall St balance-sheet summary.
B8: Godfrey Phillips India Ltd. | C8: 6110 | D8: 1335 | E8: 1215 | F8: 1525 | G8: 0 | H8: 0 | I8: 15.6 | J8: =K8/I8 -> 2293.0128 | K8: 35771 | L8: =G8-H8 -> 0 | M8: =K8+L8 -> 35771 | N8: =F8/I8 -> 97.75641 | O8: Aug 2026 | P8: FY26 Net Profit ₹1,525 Cr per company release (InvestyWise); Revenue ₹6,110 Cr and Market Cap ₹35,771 Cr per Screener.in (Aug 2026). EBITDA/EBIT estimated from Q1 FY26 EBITDA margin (~21.9%, pre the FY27 tax-driven margin shock) applied to FY26 revenue — not company-disclosed full-year figures. Net Debt simplified to nil (GPI is disclosed as 'almost debt free' per Screener); precise cash/investment balance not decomposed from available sources.
B9: Nestlé India Ltd. | C9: 24437 | D9: 5670 | E9: 4920 | F9: 3860 | G9: 0 | H9: 0 | I9: 96.42 | J9: =K9/I9 -> 2997.262 | K9: 288996 | L9: =G9-H9 -> 0 | M9: =K9+L9 -> 288996 | N9: =F9/I9 -> 40.033188 | O9: Aug 2026 | P9: Revenue ₹24,437 Cr and Net Profit ₹3,860 Cr per Screener.in (Aug 2026); EBITDA/EBIT estimated from FY26 quarterly EBITDA margins (21-26%, average ~23.2%) applied to FY26 revenue — not a single disclosed full-year figure. Shares outstanding 9.64 Cr (widely reported, face value ₹10); Net Debt simplified to nil (Nestlé India carries negligible debt).
B10: Britannia Industries Ltd. | C10: 19151.59 | D10: 3320.4 | E10: 2990 | F10: 2537.01 | G10: 0 | H10: 0 | I10: 24.07 | J10: =K10/I10 -> 5217.0752 | K10: 125575 | L10: =G10-H10 -> 0 | M10: =K10+L10 -> 125575 | N10: =F10/I10 -> 105.40133 | O10: Aug 2026 | P10: Revenue ₹19,151.59 Cr and Net Profit ₹2,537.01 Cr per company FY26 results (ScanX); TTM EBITDA ₹3,320.4 Cr per Tickertape. EBIT estimated as EBITDA less an assumed ₹330 Cr D&A run-rate. Market Cap ₹1,25,575 Cr per Screener.in (Aug 2026); Net Debt simplified to nil, consistent with Britannia's low-leverage profile.

Sheet CCA Multiples
B2: Trading Multiples
B3: EV/Revenue, EV/EBITDA and EV/EBIT use Enterprise Value; P/E uses Share Price ÷ EPS. Mean / Median / Min / Max are computed across the 4-company peer group only — ITC is shown for reference and excluded from the summary statistics.
B6: Company | C6: EV / Revenue | D6: EV / EBITDA | E6: EV / EBIT | F6: P / E
B7: ='Peer Data'!B6 -> ITC Limited (for reference) | C7: ='Peer Data'!M6/'Peer Data'!C6 -> 3.6603273 | D7: ='Peer Data'!M6/'Peer Data'!D6 -> 12.047489 | E7: ='Peer Data'!M6/'Peer Data'!E6 -> 12.852241 | F7: ='Peer Data'!J6/'Peer Data'!N6 -> 16.572348
B8: ='Peer Data'!B7 -> Hindustan Unilever Ltd. | C8: ='Peer Data'!M7/'Peer Data'!C7 -> 7.4473127 | D8: ='Peer Data'!M7/'Peer Data'!D7 -> 31.543975 | E8: ='Peer Data'!M7/'Peer Data'!E7 -> 34.608483 | F8: ='Peer Data'!J7/'Peer Data'!N7 -> 45.352891
B9: ='Peer Data'!B8 -> Godfrey Phillips India Ltd. | C9: ='Peer Data'!M8/'Peer Data'!C8 -> 5.8545008 | D9: ='Peer Data'!M8/'Peer Data'!D8 -> 26.794757 | E9: ='Peer Data'!M8/'Peer Data'!E8 -> 29.441152 | F9: ='Peer Data'!J8/'Peer Data'!N8 -> 23.456393
B10: ='Peer Data'!B9 -> Nestlé India Ltd. | C10: ='Peer Data'!M9/'Peer Data'!C9 -> 11.826165 | D10: ='Peer Data'!M9/'Peer Data'!D9 -> 50.969312 | E10: ='Peer Data'!M9/'Peer Data'!E9 -> 58.739024 | F10: ='Peer Data'!J9/'Peer Data'!N9 -> 74.86943
B11: ='Peer Data'!B10 -> Britannia Industries Ltd. | C11: ='Peer Data'!M10/'Peer Data'!C10 -> 6.5568968 | D11: ='Peer Data'!M10/'Peer Data'!D10 -> 37.819239 | E11: ='Peer Data'!M10/'Peer Data'!E10 -> 41.998328 | F11: ='Peer Data'!J10/'Peer Data'!N10 -> 49.497243
B12: Peer Group Summary Statistics (4 companies)
B14: Mean | C14: =AVERAGE(C8:C11) -> 7.9212189 | D14: =AVERAGE(D8:D11) -> 36.781821 | E14: =AVERAGE(E8:E11) -> 41.196747 | F14: =AVERAGE(F8:F11) -> 48.293989
B15: Median | C15: =MEDIAN(C8:C11) -> 7.0021048 | D15: =MEDIAN(D8:D11) -> 34.681607 | E15: =MEDIAN(E8:E11) -> 38.303406 | F15: =MEDIAN(F8:F11) -> 47.425067
B16: Min | C16: =MIN(C8:C11) -> 5.8545008 | D16: =MIN(D8:D11) -> 26.794757 | E16: =MIN(E8:E11) -> 29.441152 | F16: =MIN(F8:F11) -> 23.456393
B17: Max | C17: =MAX(C8:C11) -> 11.826165 | D17: =MAX(D8:D11) -> 50.969312 | E17: =MAX(E8:E11) -> 58.739024 | F17: =MAX(F8:F11) -> 74.86943

Sheet Implied Valuation
B2: Implied Valuation of ITC — Comparable Company Analysis
